Workbook

Sheet Product Backlog tareas Sprints
A1: Resultado de la actividad Sprint Planning
A2: Sprint Backlog con estimación de tareas para las historia de usuario del Primer Sprint
A4: Total Horas: | C4: =SUM(D7:D54) -> 336
A6: Id Historia | B6: Id Tarea | C6: Tareas o actividad | D6: Horas estimadas | E6: Fecha Inicio | F6: Fecha Termino
A7: ='Product Backlog tareas Sprint 1'!A7 -> SS-H01 | B7: ='Product Backlog tareas Sprint 1'!B7 -> T-01 | C7: ='Product Backlog tareas Sprint 1'!C7 -> Analizar y definir la problemática, propósito y alcance inicial del proyecto SmartStock. | D7: ='Product Backlog tareas Sprint 1'!D7 -> 7 | E7: 46261 | F7: 46261 | G7: Sprint 1 27/08 → 02/09
A8: ='Product Backlog tareas Sprint 1'!A8 -> SS-H01 | B8: ='Product Backlog tareas Sprint 1'!B8 -> T-02 | C8: ='Product Backlog tareas Sprint 1'!C8 -> Completar la definición del proyecto y Acta de Constitución, incluyendo objetivos, interesados y responsabilidades principales. | D8: ='Product Backlog tareas Sprint 1'!D8 -> 8 | E8: 46261 | F8: 46262
A9: ='Product Backlog tareas Sprint 1'!A9 -> SS-H02 | B9: ='Product Backlog tareas Sprint 1'!B9 -> T-03 | C9: ='Product Backlog tareas Sprint 1'!C9 -> Identificar y documentar los requerimientos funcionales de SmartStock. | D9: ='Product Backlog tareas Sprint 1'!D9 -> 8 | E9: 46262 | F9: 46263
A10: ='Product Backlog tareas Sprint 1'!A10 -> SS-H02 | B10: ='Product Backlog tareas Sprint 1'!B10 -> T-04 | C10: ='Product Backlog tareas Sprint 1'!C10 -> Identificar, clasificar y validar los requerimientos no funcionales y revisar la matriz de requerimientos. | D10: ='Product Backlog tareas Sprint 1'!D10 -> 8 | E10: 46263 | F10: 46264
A11: ='Product Backlog tareas Sprint 1'!A11 -> SS-H03 | B11: ='Product Backlog tareas Sprint 1'!B11 -> T-05 | C11: ='Product Backlog tareas Sprint 1'!C11 -> Analizar y seleccionar las tecnologías y herramientas que se utilizarán en el proyecto. | D11: ='Product Backlog tareas Sprint 1'!D11 -> 7 | E11: 46264 | F11: 46265
A12: ='Product Backlog tareas Sprint 1'!A12 -> SS-H03 | B12: ='Product Backlog tareas Sprint 1'!B12 -> T-06 | C12: ='Product Backlog tareas Sprint 1'!C12 -> Definir la arquitectura preliminar y validar técnicamente la propuesta con el equipo. | D12: ='Product Backlog tareas Sprint 1'!D12 -> 7 | E12: 46265 | F12: 46266
A13: ='Product Backlog tareas Sprint 1'!A13 -> SS-H04 | B13: ='Product Backlog tareas Sprint 1'!B13 -> T-07 | C13: ='Product Backlog tareas Sprint 1'!C13 -> Organizar el repositorio GitHub, estructura de carpetas, documentación y evidencias de la Fase 1. | D13: ='Product Backlog tareas Sprint 1'!D13 -> 5 | E13: 46266 | F13: 46266
A14: ='Product Backlog tareas Sprint 1'!A14 -> SS-H04 | B14: ='Product Backlog tareas Sprint 1'!B14 -> T-08 | C14: ='Product Backlog tareas Sprint 1'!C14 -> Revisar, corregir y consolidar la documentación y evidencias generadas durante el Sprint. | D14: ='Product Backlog tareas Sprint 1'!D14 -> 6 | E14: 46266 | F14: 46267
A15: ='Product Backlog tareas Sprint 2'!A7 -> SS-H05 | B15: ='Product Backlog tareas Sprint 2'!B7 -> T-09 | C15: ='Product Backlog tareas Sprint 2'!C7 -> Definir y organizar las épicas principales del proyecto SmartStock. | D15: ='Product Backlog tareas Sprint 2'!D7 -> 6 | E15: 46268 | F15: 46268 | G15: Sprint 2 03/09 → 09/09
A16: ='Product Backlog tareas Sprint 2'!A8 -> SS-H05 | B16: ='Product Backlog tareas Sprint 2'!B8 -> T-10 | C16: ='Product Backlog tareas Sprint 2'!C8 -> Elaborar y revisar las historias de usuario y sus criterios de aceptación. | D16: ='Product Backlog tareas Sprint 2'!D8 -> 10 | E16: 46268 | F16: 46269
A17: ='Product Backlog tareas Sprint 2'!A9 -> SS-H06 | B17: ='Product Backlog tareas Sprint 2'!B9 -> T-11 | C17: ='Product Backlog tareas Sprint 2'!C9 -> Priorizar las épicas e historias del Product Backlog utilizando la técnica MoSCoW. | D17: ='Product Backlog tareas Sprint 2'!D9 -> 6 | E17: 46269 | F17: 46270
A18: ='Product Backlog tareas Sprint 2'!A10 -> SS-H06 | B18: ='Product Backlog tareas Sprint 2'!B10 -> T-12 | C18: ='Product Backlog tareas Sprint 2'!C10 -> Realizar Planning Poker y asignar puntos de historia utilizando la escala de Fibonacci. | D18: ='Product Backlog tareas Sprint 2'!D10 -> 7 | E18: 46270 | F18: 46271
A19: ='Product Backlog tareas Sprint 2'!A11 -> SS-H07 | B19: ='Product Backlog tareas Sprint 2'!B11 -> T-13 | C19: ='Product Backlog tareas Sprint 2'!C11 -> Definir la cantidad de Sprints y distribuir las historias según prioridad y dependencia. | D19: ='Product Backlog tareas Sprint 2'!D11 -> 7 | E19: 46271 | F19: 46272
A20: ='Product Backlog tareas Sprint 2'!A12 -> SS-H107 | B20: ='Product Backlog tareas Sprint 2'!B12 -> T-14 | C20: ='Product Backlog tareas Sprint 2'!C12 -> Elaborar los Sprint Backlog con tareas y estimación de horas para cada iteración. | D20: ='Product Backlog tareas Sprint 2'!D12 -> 8 | E20: 46272 | F20: 46273
A21: ='Product Backlog tareas Sprint 2'!A13 -> SS-H08 | B21: ='Product Backlog tareas Sprint 2'!B13 -> T-15 | C21: ='Product Backlog tareas Sprint 2'!C13 -> Revisar la coherencia entre requerimientos, épicas, historias, planificación y demás documentos de la Fase 1. | D21: ='Product Backlog tareas Sprint 2'!D13 -> 6 | E21: 46273 | F21: 46274
A22: ='Product Backlog tareas Sprint 2'!A14 -> SS-H08 | B22: ='Product Backlog tareas Sprint 2'!B14 -> T-16 | C22: ='Product Backlog tareas Sprint 2'!C14 -> Consolidar, corregir y preparar la documentación y evidencias finales de la Fase 1. | D22: ='Product Backlog tareas Sprint 2'!D14 -> 6 | E22: 46274 | F22: 46275
A23: ='Product Backlog tareas Sprint 3'!A7 -> SS-H09 / SS-H20 / SS-H10 | B23: ='Product Backlog tareas Sprint 3'!B7 -> T-17 | C23: ='Product Backlog tareas Sprint 3'!C7 -> Configurar el entorno de desarrollo, estructura inicial del sistema y conexión con la base de datos. | D23: ='Product Backlog tareas Sprint 3'!D7 -> 7 | E23: 46275 | F23: 46276 | G23: Sprint 3 10/09 → 30/09
A24: ='Product Backlog tareas Sprint 3'!A8 -> SS-H09 / SS-H20 | B24: ='Product Backlog tareas Sprint 3'!B8 -> T-18 | C24: ='Product Backlog tareas Sprint 3'!C8 -> Diseñar e implementar el modelo de datos para usuarios, roles y autenticación. | D24: ='Product Backlog tareas Sprint 3'!D8 -> 8 | E24: 46277 | F24: 46279
A25: ='Product Backlog tareas Sprint 3'!A9 -> SS-H09 | B25: ='Product Backlog tareas Sprint 3'!B9 -> T-19 | C25: ='Product Backlog tareas Sprint 3'!C9 -> Implementar inicio y cierre de sesión, validación de credenciales y control de cuentas desactivadas. | D25: ='Product Backlog tareas Sprint 3'!D9 -> 6 | E25: 46280 | F25: 46281
A26: ='Product Backlog tareas Sprint 3'!A10 -> SS-H20 | B26: ='Product Backlog tareas Sprint 3'!B10 -> T-20 | C26: ='Product Backlog tareas Sprint 3'!C10 -> Implementar creación, edición, activación y desactivación de usuarios. | D26: ='Product Backlog tareas Sprint 3'!D10 -> 8 | E26: 46282 | F26: 46284
A27: ='Product Backlog tareas Sprint 3'!A11 -> SS-H20 | B27: ='Product Backlog tareas Sprint 3'!B11 -> T-21 | C27: ='Product Backlog tareas Sprint 3'!C11 -> Implementar asignación de roles, permisos y control de acceso según tipo de usuario. | D27: ='Product Backlog tareas Sprint 3'!D11 -> 8 | E27: 46285 | F27: 46287
A28: ='Product Backlog tareas Sprint 3'!A12 -> SS-H10 | B28: ='Product Backlog tareas Sprint 3'!B12 -> T-22 | C28: ='Product Backlog tareas Sprint 3'!C12 -> Implementar modelo de datos y funcionalidades básicas para registrar, editar y desactivar productos. | D28: ='Product Backlog tareas Sprint 3'!D12 -> 7 | E28: 46288 | F28: 46290
A29: ='Product Backlog tareas Sprint 3'!A13 -> SS-H09 / SS-H10 / SS-H20 | B29: ='Product Backlog tareas Sprint 3'!B13 -> T-23 | C29: ='Product Backlog tareas Sprint 3'!C13 -> Integrar interfaces, backend y base de datos, realizando pruebas funcionales de los módulos desarrollados. | D29: ='Product Backlog tareas Sprint 3'!D13 -> 7 | E29: 46291 | F29: 46293
A30: ='Product Backlog tareas Sprint 3'!A14 -> SS-H09 / SS-H10 / SS-H20 | B30: ='Product Backlog tareas Sprint 3'!B14 -> T-24 | C30: ='Product Backlog tareas Sprint 3'!C14 -> Documentar el incremento desarrollado y recopilar las evidencias correspondientes al Sprint. | D30: ='Product Backlog tareas Sprint 3'!D14 -> 5 | E30: 46294 | F30: 46295
A31: ='Product Backlog tareas Sprint 4'!A7 -> SS-H12 | B31: ='Product Backlog tareas Sprint 4'!B7 -> T-25 | C31: ='Product Backlog tareas Sprint 4'!C7 -> Implementar la gestión de sucursales, incluyendo creación, edición y consulta. | D31: ='Product Backlog tareas Sprint 4'!D7 -> 6 | E31: 46296 | F31: 46298 | G31: Sprint 4 01/10 → 22/10
A32: ='Product Backlog tareas Sprint 4'!A8 -> SS-H14 | B32: ='Product Backlog tareas Sprint 4'!B8 -> T-26 | C32: ='Product Backlog tareas Sprint 4'!C8 -> Implementar la gestión de bodegas asociadas a sucursales, incluyendo edición y desactivación lógica. | D32: ='Product Backlog tareas Sprint 4'!D8 -> 7 | E32: 46299 | F32: 46305
A33: ='Product Backlog tareas Sprint 4'!A9 -> SS-H15 | B33: ='Product Backlog tareas Sprint 4'!B9 -> T-27 | C33: ='Product Backlog tareas Sprint 4'!C9 -> Implementar pasillos, estanterías, niveles, posiciones y asignación de productos a ubicaciones físicas. | D33: ='Product Backlog tareas Sprint 4'!D9 -> 8 | E33: 46295 | F33: 46286
A34: ='Product Backlog tareas Sprint 4'!A10 -> SS-H11 | B34: ='Product Backlog tareas Sprint 4'!B10 -> T-28 | C34: ='Product Backlog tareas Sprint 4'!C10 -> Implementar entradas y salidas de inventario mediante escaneo de código de barras o ingreso manual. | D34: ='Product Backlog tareas Sprint 4'!D10 -> 10 | E34: 46297 | F34: 46287
A35: ='Product Backlog tareas Sprint 4'!A11 -> SS-H16 | B35: ='Product Backlog tareas Sprint 4'!B11 -> T-29 | C35: ='Product Backlog tareas Sprint 4'!C11 -> Implementar transferencias de productos entre bodegas con actualización del stock de origen y destino. | D35: ='Product Backlog tareas Sprint 4'!D11 -> 7 | E35: 46299 | F35: 46288
A36: ='Product Backlog tareas Sprint 4'!A12 -> SS-H17 | B36: ='Product Backlog tareas Sprint 4'!B12 -> T-30 | C36: ='Product Backlog tareas Sprint 4'!C12 -> Implementar registro de mermas con cantidad, motivo, responsable y actualización del stock. | D36: ='Product Backlog tareas Sprint 4'!D12 -> 6 | E36: 46301 | F36: 46289
A37: ='Product Backlog tareas Sprint 4'!A13 -> SS-H11 / H12 / H14 / H15 / H16 / H17 | B37: ='Product Backlog tareas Sprint 4'!B13 -> T-31 | C37: ='Product Backlog tareas Sprint 4'!C13 -> Integrar los módulos desarrollados y ejecutar pruebas funcionales de los principales flujos de inventario. | D37: ='Product Backlog tareas Sprint 4'!D13 -> 8 | E37: 46303 | F37: 46290
A38: ='Product Backlog tareas Sprint 4'!A14 -> SS-H11 / H12 / H14 / H15 / H16 / H17 | B38: ='Product Backlog tareas Sprint 4'!B14 -> T-32 | C38: ='Product Backlog tareas Sprint 4'!C14 -> Documentar el incremento desarrollado y recopilar evidencias del Sprint. | D38: ='Product Backlog tareas Sprint 4'!D14 -> 4 | E38: 46305 | F38: 46291
A39: ='Product Backlog tareas Sprint 5'!A7 -> SS-H18 | B39: ='Product Backlog tareas Sprint 5'!B7 -> T-33 | C39: ='Product Backlog tareas Sprint 5'!C7 -> Implementar la consulta de stock por producto, sucursal, bodega y ubicación física. | D39: ='Product Backlog tareas Sprint 5'!D7 -> 7 | G39: Sprint 5 23/10 → 19/11
A40: ='Product Backlog tareas Sprint 5'!A8 -> SS-H13 | B40: ='Product Backlog tareas Sprint 5'!B8 -> T-34 | C40: ='Product Backlog tareas Sprint 5'!C8 -> Implementar la configuración de stock mínimo y generación automática de alertas. | D40: ='Product Backlog tareas Sprint 5'!D8 -> 7
A41: ='Product Backlog tareas Sprint 5'!A9 -> SS-H13 | B41: ='Product Backlog tareas Sprint 5'!B9 -> T-35 | C41: ='Product Backlog tareas Sprint 5'!C9 -> Implementar la visualización, seguimiento y cierre automático de alertas de stock. | D41: ='Product Backlog tareas Sprint 5'!D9 -> 6
A42: ='Product Backlog tareas Sprint 5'!A10 -> SS-H19 | B42: ='Product Backlog tareas Sprint 5'!B10 -> T-36 | C42: ='Product Backlog tareas Sprint 5'!C10 -> Implementar historial, detalle y filtros de movimientos para mantener la trazabilidad del inventario. | D42: ='Product Backlog tareas Sprint 5'!D10 -> 9
...

Sheet Product Backlog tareas Sprint 1
A1: Resultado de la actividad Sprint Planning
A2: Sprint Backlog con estimación de tareas para las historia de usuario del Primer Sprint
A4: Total Horas: | C4: =SUM(D7:D14) -> 56
A6: Id Historia | B6: Id Tarea | C6: Tareas o actividad | D6: Horas estimadas
A7: SS-H01 | B7: T-01 | C7: Analizar y definir la problemática, propósito y alcance inicial del proyecto SmartStock. | D7: 7
A8: SS-H01 | B8: T-02 | C8: Completar la definición del proyecto y Acta de Constitución, incluyendo objetivos, interesados y responsabilidades principales. | D8: 8
A9: SS-H02 | B9: T-03 | C9: Identificar y documentar los requerimientos funcionales de SmartStock. | D9: 8
A10: SS-H02 | B10: T-04 | C10: Identificar, clasificar y validar los requerimientos no funcionales y revisar la matriz de requerimientos. | D10: 8
A11: SS-H03 | B11: T-05 | C11: Analizar y seleccionar las tecnologías y herramientas que se utilizarán en el proyecto. | D11: 7
A12: SS-H03 | B12: T-06 | C12: Definir la arquitectura preliminar y validar técnicamente la propuesta con el equipo. | D12: 7
A13: SS-H04 | B13: T-07 | C13: Organizar el repositorio GitHub, estructura de carpetas, documentación y evidencias de la Fase 1. | D13: 5
A14: SS-H04 | B14: T-08 | C14: Revisar, corregir y consolidar la documentación y evidencias generadas durante el Sprint. | D14: 6

Sheet Product Backlog tareas Sprint 2
A1: Resultado de la actividad Sprint Planning
A2: Sprint Backlog con estimación de tareas para las historia de usuario del Primer Sprint
A4: Total Horas: | C4: =SUM(D7:D14) -> 56
A6: Id Historia | B6: Id Tarea | C6: Tareas o actividad | D6: Horas estimadas
A7: SS-H05 | B7: T-09 | C7: Definir y organizar las épicas principales del proyecto SmartStock. | D7: 6
A8: SS-H05 | B8: T-10 | C8: Elaborar y revisar las historias de usuario y sus criterios de aceptación. | D8: 10
A9: SS-H06 | B9: T-11 | C9: Priorizar las épicas e historias del Product Backlog utilizando la técnica MoSCoW. | D9: 6
A10: SS-H06 | B10: T-12 | C10: Realizar Planning Poker y asignar puntos de historia utilizando la escala de Fibonacci. | D10: 7
A11: SS-H07 | B11: T-13 | C11: Definir la cantidad de Sprints y distribuir las historias según prioridad y dependencia. | D11: 7
A12: SS-H107 | B12: T-14 | C12: Elaborar los Sprint Backlog con tareas y estimación de horas para cada iteración. | D12: 8
A13: SS-H08 | B13: T-15 | C13: Revisar la coherencia entre requerimientos, épicas, historias, planificación y demás documentos de la Fase 1. | D13: 6
A14: SS-H08 | B14: T-16 | C14: Consolidar, corregir y preparar la documentación y evidencias finales de la Fase 1. | D14: 6

Sheet Product Backlog tareas Sprint 3
A1: Resultado de la actividad Sprint Planning
A2: Sprint Backlog con estimación de tareas para las historia de usuario del Primer Sprint
A4: Total Horas: | C4: =SUM(D7:D14) -> 56
A6: Id Historia | B6: Id Tarea | C6: Tareas o actividad | D6: Horas estimadas
A7: SS-H09 / SS-H20 / SS-H10 | B7: T-17 | C7: Configurar el entorno de desarrollo, estructura inicial del sistema y conexión con la base de datos. | D7: 7
A8: SS-H09 / SS-H20 | B8: T-18 | C8: Diseñar e implementar el modelo de datos para usuarios, roles y autenticación. | D8: 8
A9: SS-H09 | B9: T-19 | C9: Implementar inicio y cierre de sesión, validación de credenciales y control de cuentas desactivadas. | D9: 6
A10: SS-H20 | B10: T-20 | C10: Implementar creación, edición, activación y desactivación de usuarios. | D10: 8
A11: SS-H20 | B11: T-21 | C11: Implementar asignación de roles, permisos y control de acceso según tipo de usuario. | D11: 8
A12: SS-H10 | B12: T-22 | C12: Implementar modelo de datos y funcionalidades básicas para registrar, editar y desactivar productos. | D12: 7
A13: SS-H09 / SS-H10 / SS-H20 | B13: T-23 | C13: Integrar interfaces, backend y base de datos, realizando pruebas funcionales de los módulos desarrollados. | D13: 7
A14: SS-H09 / SS-H10 / SS-H20 | B14: T-24 | C14: Documentar el incremento desarrollado y recopilar las evidencias correspondientes al Sprint. | D14: 5

Sheet Product Backlog tareas Sprint 4
A1: Resultado de la actividad Sprint Planning
A2: Sprint Backlog con estimación de tareas para las historia de usuario del Primer Sprint
A4: Total Horas: | C4: =SUM(D7:D14) -> 56
A6: Id Historia | B6: Id Tarea | C6: Tareas o actividad | D6: Horas estimadas
A7: SS-H12 | B7: T-25 | C7: Implementar la gestión de sucursales, incluyendo creación, edición y consulta. | D7: 6
A8: SS-H14 | B8: T-26 | C8: Implementar la gestión de bodegas asociadas a sucursales, incluyendo edición y desactivación lógica. | D8: 7
A9: SS-H15 | B9: T-27 | C9: Implementar pasillos, estanterías, niveles, posiciones y asignación de productos a ubicaciones físicas. | D9: 8
A10: SS-H11 | B10: T-28 | C10: Implementar entradas y salidas de inventario mediante escaneo de código de barras o ingreso manual. | D10: 10
A11: SS-H16 | B11: T-29 | C11: Implementar transferencias de productos entre bodegas con actualización del stock de origen y destino. | D11: 7
A12: SS-H17 | B12: T-30 | C12: Implementar registro de mermas con cantidad, motivo, responsable y actualización del stock. | D12: 6
A13: SS-H11 / H12 / H14 / H15 / H16 / H17 | B13: T-31 | C13: Integrar los módulos desarrollados y ejecutar pruebas funcionales de los principales flujos de inventario. | D13: 8
A14: SS-H11 / H12 / H14 / H15 / H16 / H17 | B14: T-32 | C14: Documentar el incremento desarrollado y recopilar evidencias del Sprint. | D14: 4

Sheet Product Backlog tareas Sprint 5
A1: Resultado de la actividad Sprint Planning
A2: Sprint Backlog con estimación de tareas para las historia de usuario del Primer Sprint
A4: Total Horas: | C4: =SUM(D7:D14) -> 56
A6: Id Historia | B6: Id Tarea | C6: Tareas o actividad | D6: Horas estimadas
A7: SS-H18 | B7: T-33 | C7: Implementar la consulta de stock por producto, sucursal, bodega y ubicación física. | D7: 7
A8: SS-H13 | B8: T-34 | C8: Implementar la configuración de stock mínimo y generación automática de alertas. | D8: 7
A9: SS-H13 | B9: T-35 | C9: Implementar la visualización, seguimiento y cierre automático de alertas de stock. | D9: 6
A10: SS-H19 | B10: T-36 | C10: Implementar historial, detalle y filtros de movimientos para mantener la trazabilidad del inventario. | D10: 9
A11: SS-H21 | B11: T-37 | C11: Implementar conteos físicos y comparación entre inventario físico y stock registrado. | D11: 8
A12: SS-H22 | B12: T-38 | C12: Implementar ajustes de inventario con cantidad, motivo, responsable y registro de trazabilidad. | D12: 7
A13: SS-H13 / H18 / H19 / H21 / H22 | B13: T-39 | C13: Integrar los módulos de control de inventario y ejecutar pruebas funcionales de los principales escenarios. | D13: 8
A14: SS-H13 / H18 / H19 / H21 / H22 | B14: T-40 | C14: Documentar el incremento desarrollado y recopilar evidencias del Sprint. | D14: 4

Sheet Product Backlog tareas Sprint 6
A1: Resultado de la actividad Sprint Planning
A2: Sprint Backlog con estimación de tareas para las historia de usuario del Primer Sprint
A4: Total Horas: | C4: =SUM(D7:D14) -> 56
A6: Id Historia | B6: Id Tarea | C6: Tareas o actividad | D6: Horas estimadas
A7: SS-H09 a SS-H22 | B7: T-41 | C7: Integrar los módulos desarrollados y verificar el flujo completo de funcionamiento de SmartStock. | D7: 10
A8: SS-H09 a SS-H22 | B8: T-42 | C8: Verificar la comunicación y consistencia de datos entre interfaces, APIs y base de datos. | D8: 8
A9: SS-H09 a SS-H22 | B9: T-43 | C9: Ejecutar pruebas funcionales e integrales sobre los principales flujos del sistema. | D9: 9
A10: SS-H09 / SS-H20 | B10: T-44 | C10: Validar autenticación, roles, permisos y restricciones de acceso del sistema. | D10: 6
A11: SS-H09 a SS-H22 | B11: T-45 | C11: Corregir errores e incidencias detectadas y realizar ajustes finales de funcionamiento. | D11: 8
A12: SS-H09 a SS-H22 | B12: T-46 | C12: Preparar y realizar el despliegue de la versión final de SmartStock. | D12: 6
A13: SS-H09 a SS-H22 | B13: T-47 | C13: Completar documentación técnica, manuales, evidencias y registros finales del proyecto. | D13: 5
A14: SS-H09 a SS-H22 | B14: T-48 | C14: Preparar la demostración, presentación y entrega final de SmartStock. | D14: 4
